<?xml version="1.0" encoding="utf-8"?>
<!-- 
  This URDF was automatically created by SolidWorks to URDF Exporter! Originally created by Stephen Brawner (brawner@gmail.com) 
  Commit Version: 1.6.0-4-g7f85cfe  Build Version: 1.6.7995.38578
  For more information, please see http://wiki.ros.org/sw_urdf_exporter
  
  This file has been manually refactored for clarity and organization.
-->
<robot name="surenaV">

  <!-- ===================================================================================== -->
  <!-- |                                 GAZEBO PLUGINS                                    | -->
  <!-- ===================================================================================== -->
  <!-- Gazebo ROS Control Plugin -->
  <gazebo>
    <plugin name="gazebo_ros_control" filename="libgazebo_ros_control.so">
      <robotNamespace>/surenaV</robotNamespace>
      <robotSimType>gazebo_ros_control/DefaultRobotHWSim</robotSimType>
    </plugin>
  </gazebo>


  <!-- ===================================================================================== -->
  <!-- |                                  LINKS & JOINTS                                   | -->
  <!-- ===================================================================================== -->

  <!-- BASE LINK -->
  <link name="base_link">
    <inertial>
      <origin xyz="0.05495 -0.00046591 1.1042" rpy="0 0 0" />
      <mass value="13.59" />
      <inertia ixx="0.47" ixy="-0.19" ixz="0.11" iyy="0.84" iyz="-0.04" izz="0.66" />
    </inertial>
    <visual>
      <origin xyz="0 0 0" rpy="0 0 0" />
      <geometry>
        <mesh filename="package://surenaV_description/meshes/base_link.STL" />
      </geometry>
      <material name="">
        <color rgba="0.79216 0.81961 0.93333 1" />
      </material>
    </visual>
    <collision>
      <origin xyz="0 0 0" rpy="0 0 0" />
      <geometry>
        <mesh filename="package://surenaV_description/meshes/base_link.STL" />
      </geometry>
    </collision>
  </link>

  <!-- HEAD -->
  <link name="head_yaw">
    <inertial>
      <origin xyz="-0.0036927 0.00094602 0.055932" rpy="0 0 0" />
      <mass value="1.65" />
      <inertia ixx="0.12" ixy="-0.07" ixz="-0.05" iyy="0.26" iyz="0.02" izz="0.21" />
    </inertial>
    <visual>
      <origin xyz="0 0 0" rpy="0 0 0" />
      <geometry>
        <mesh filename="package://surenaV_description/meshes/head_yaw.STL" />
      </geometry>
      <material name="">
        <color rgba="0.79216 0.81961 0.93333 1" />
      </material>
    </visual>
    <collision>
      <origin xyz="0 0 0" rpy="0 0 0" />
      <geometry>
        <mesh filename="package://surenaV_description/meshes/head_yaw.STL" />
      </geometry>
    </collision>
  </link>
  <joint name="head_yaw_joint" type="revolute">
    <origin xyz="0.0725 0 1.3497" rpy="0 0 0" />
    <parent link="base_link" />
    <child link="head_yaw" />
    <axis xyz="0 0 1" />
    <limit lower="-1.57" upper="1.57" effort="1000" velocity="0.5" />
    <dynamics damping="0.7" friction="0.3" />
  </joint>

  <link name="head_pitch">
    <inertial>
      <origin xyz="-0.00066333 -0.0291 0.067023" rpy="0 0 0" />
      <mass value="1.68" />
      <inertia ixx="0.13" ixy="-0.07" ixz="-0.06" iyy="0.27" iyz="0.03" izz="0.22" />
    </inertial>
    <visual>
      <origin xyz="0 0 0" rpy="0 0 0" />
      <geometry>
        <mesh filename="package://surenaV_description/meshes/head_pitch.STL" />
      </geometry>
      <material name="">
        <color rgba="0.79216 0.81961 0.93333 1" />
      </material>
    </visual>
    <collision>
      <origin xyz="0 0 0" rpy="0 0 0" />
      <geometry>
        <mesh filename="package://surenaV_description/meshes/head_pitch.STL" />
      </geometry>
    </collision>
  </link>
  <joint name="head_pitch_joint" type="revolute">
    <origin xyz="0 0.0271 0.07175" rpy="0 0 0" />
    <parent link="head_yaw" />
    <child link="head_pitch" />
    <axis xyz="0 1 0" />
    <limit lower="-1.57" upper="1.57" effort="1000" velocity="0.5" />
    <dynamics damping="0.7" friction="0.3" />
  </joint>

  <link name="head_roll">
    <inertial>
      <origin xyz="-0.044066 -0.0015813 0.011272" rpy="0 0 0" />
      <mass value="1.96" />
      <inertia ixx="0.15" ixy="-0.09" ixz="-0.09" iyy="0.34" iyz="0.04" izz="0.28" />
    </inertial>
    <visual>
      <origin xyz="0 0 0" rpy="0 0 0" />
      <geometry>
        <mesh filename="package://surenaV_description/meshes/head_roll.STL" />
      </geometry>
      <material name="">
        <color rgba="0.79216 0.81961 0.93333 1" />
      </material>
    </visual>
    <collision>
      <origin xyz="0 0 0" rpy="0 0 0" />
      <geometry>
        <mesh filename="package://surenaV_description/meshes/head_roll.STL" />
      </geometry>
    </collision>
  </link>
  <joint name="head_roll_joint" type="revolute">
    <origin xyz="0.0296 -0.0291 0.0825" rpy="0 0 0" />
    <parent link="head_pitch" />
    <child link="head_roll" />
    <axis xyz="1 0 0" />
    <limit lower="-1.57" upper="1.57" effort="1000" velocity="0.5" />
    <dynamics damping="0.7" friction="0.3" />
  </joint>

  <!-- RIGHT LEG -->
  <link name="r_hip_yaw">
    <inertial>
      <origin xyz="-0.069849 0.00016756 -0.078178" rpy="0 0 0" />
      <mass value="3.17" />
      <inertia ixx="0.01" ixy="0.00" ixz="0.00" iyy="0.02" iyz="0.00" izz="0.02" />
    </inertial>
    <visual>
      <origin xyz="0 0 0" rpy="0 0 0" />
      <geometry>
        <mesh filename="package://surenaV_description/meshes/r_hip_yaw.STL" />
      </geometry>
      <material name="">
        <color rgba="0.79216 0.81961 0.93333 1" />
      </material>
    </visual>
    <collision>
      <origin xyz="0 0 0" rpy="0 0 0" />
      <geometry>
        <mesh filename="package://surenaV_description/meshes/r_hip_yaw.STL" />
      </geometry>
    </collision>
  </link>
  <joint name="r_hip_yaw_joint" type="revolute">
    <origin xyz="0.043012 -0.1 0.87631" rpy="0 0 0" />
    <parent link="base_link" />
    <child link="r_hip_yaw" />
    <axis xyz="0 0 1" />
    <limit lower="-1.57" upper="1.57" effort="1000" velocity="0.5" />
    <dynamics damping="0.7" friction="0.3" />
  </joint>

  <link name="r_hip_roll">
    <inertial>
      <origin xyz="0.0035233 0.012172 -0.00020667" rpy="0 0 0" />
      <mass value="2.44" />
      <inertia ixx="0.01" ixy="0.00" ixz="0.00" iyy="0.00" iyz="0.00" izz="0.01" />
    </inertial>
    <visual>
      <origin xyz="0 0 0" rpy="0 0 0" />
      <geometry>
        <mesh filename="package://surenaV_description/meshes/r_hip_roll.STL" />
      </geometry>
      <material name="">
        <color rgba="0.79216 0.81961 0.93333 1" />
      </material>
    </visual>
    <collision>
      <origin xyz="0 0 0" rpy="0 0 0" />
      <geometry>
        <mesh filename="package://surenaV_description/meshes/r_hip_roll.STL" />
      </geometry>
    </collision>
  </link>
  <joint name="r_hip_roll_joint" type="revolute">
    <origin xyz="0 0 -0.1113" rpy="0 0 0" />
    <parent link="r_hip_yaw" />
    <child link="r_hip_roll" />
    <axis xyz="1 0 0" />
    <limit lower="-1.57" upper="1.57" effort="1000" velocity="0.5" />
    <dynamics damping="0.7" friction="0.3" />
  </joint>

  <link name="r_hip_pitch">
    <inertial>
      <origin xyz="0.0025608 0.012621 -0.178" rpy="0 0 0" />
      <mass value="5.27" />
      <inertia ixx="0.05" ixy="0.00" ixz="0.00" iyy="0.04" iyz="0.00" izz="0.02" />
    </inertial>
    <visual>
      <origin xyz="0 0 0" rpy="0 0 0" />
      <geometry>
        <mesh filename="package://surenaV_description/meshes/r_hip_pitch.STL" />
      </geometry>
      <material name="">
        <color rgba="0.79216 0.81961 0.93333 1" />
      </material>
    </visual>
    <collision>
      <origin xyz="0 0 0" rpy="0 0 0" />
      <geometry>
        <mesh filename="package://surenaV_description/meshes/r_hip_pitch.STL" />
      </geometry>
    </collision>
  </link>
  <joint name="r_hip_pitch_joint" type="revolute">
    <origin xyz="0 0 0" rpy="0 0 0" />
    <parent link="r_hip_roll" />
    <child link="r_hip_pitch" />
    <axis xyz="0 1 0" />
    <limit lower="-1.57" upper="1.57" effort="1000" velocity="0.5" />
    <dynamics damping="0.7" friction="0.3" />
  </joint>

  <link name="r_knee">
    <inertial>
      <origin xyz="0.0066463 0.0011462 -0.085758" rpy="0 0 0" />
      <mass value="2.19" />
      <inertia ixx="0.03" ixy="0.00" ixz="0.00" iyy="0.03" iyz="0.00" izz="0.01" />
    </inertial>
    <visual>
      <origin xyz="0 0 0" rpy="0 0 0" />
      <geometry>
        <mesh filename="package://surenaV_description/meshes/r_knee.STL" />
      </geometry>
      <material name="">
        <color rgba="0.79216 0.81961 0.93333 1" />
      </material>
    </visual>
    <collision>
      <origin xyz="0 0 0" rpy="0 0 0" />
      <geometry>
        <mesh filename="package://surenaV_description/meshes/r_knee.STL" />
      </geometry>
    </collision>
  </link>
  <joint name="r_knee_joint" type="revolute">
    <origin xyz="0 0 -0.36006" rpy="0 0 0" />
    <parent link="r_hip_pitch" />
    <child link="r_knee" />
    <axis xyz="0 1 0" />
    <limit lower="-1.57" upper="1.57" effort="1000" velocity="0.5" />
    <dynamics damping="0.7" friction="0.3" />
  </joint>

  <link name="r_ankle_pitch">
    <inertial>
      <origin xyz="-1.3629E-05 0.0034024 0.0015737" rpy="0 0 0" />
      <mass value="0.15" />
      <inertia ixx="0" ixy="1.3944E-09" ixz="0" iyy="0" iyz="0" izz="0" />
    </inertial>
    <visual>
      <origin xyz="0 0 0" rpy="0 0 0" />
      <geometry>
        <mesh filename="package://surenaV_description/meshes/r_ankle_pitch.STL" />
      </geometry>
      <material name="">
        <color rgba="0.79216 0.81961 0.93333 1" />
      </material>
    </visual>
    <collision>
      <origin xyz="0 0 0" rpy="0 0 0" />
      <geometry>
        <mesh filename="package://surenaV_description/meshes/r_ankle_pitch.STL" />
      </geometry>
    </collision>
  </link>
  <joint name="r_ankle_pitch_joint" type="revolute">
    <origin xyz="0 0 -0.35001" rpy="0 0 0" />
    <parent link="r_knee" />
    <child link="r_ankle_pitch" />
    <axis xyz="0 1 0" />
    <limit lower="-1.57" upper="1.57" effort="1000" velocity="0.5" />
    <dynamics damping="0.7" friction="0.3" />
  </joint>

  <link name="r_ankle_roll">
    <inertial>
      <origin xyz="0.032019 -0.0010731 -0.039192" rpy="0 0 0" />
      <mass value="1.93" />
      <inertia ixx="0.00" ixy="0.00" ixz="0.00" iyy="0.01" iyz="0.00" izz="0.01" />
    </inertial>
    <visual>
      <origin xyz="0 0 0" rpy="0 0 0" />
      <geometry>
        <mesh filename="package://surenaV_description/meshes/r_ankle_roll.STL" />
      </geometry>
      <material name="">
        <color rgba="0.79216 0.81961 0.93333 1" />
      </material>
    </visual>
    <collision>
      <origin xyz="0 0 0" rpy="0 0 0" />
      <geometry>
        <mesh filename="package://surenaV_description/meshes/r_ankle_roll.STL" />
      </geometry>
      <surface>
        <friction>
          <ode>
            <mu>100</mu>
            <mu2>100</mu2>
          </ode>
        </friction>
      </surface>
    </collision>
  </link>
  <joint name="r_ankle_roll_joint" type="revolute">
    <origin xyz="0 0 0" rpy="0 0 0" />
    <parent link="r_ankle_pitch" />
    <child link="r_ankle_roll" />
    <axis xyz="1 0 0" />
    <limit lower="-1.57" upper="1.57" effort="1000" velocity="0.5" />
    <dynamics damping="0.7" friction="0.3" />
  </joint>

  <!-- LEFT LEG -->
  <link name="l_hip_yaw">
    <inertial>
      <origin xyz="-0.069213 0.00011237 -0.068241" rpy="0 0 0" />
      <mass value="3.17" />
      <inertia ixx="0.01" ixy="0.00" ixz="0.00" iyy="0.02" iyz="0.00" izz="0.02" />
    </inertial>
    <visual>
      <origin xyz="0 0 0" rpy="0 0 0" />
      <geometry>
        <mesh filename="package://surenaV_description/meshes/l_hip_yaw.STL" />
      </geometry>
      <material name="">
        <color rgba="0.79216 0.81961 0.93333 1" />
      </material>
    </visual>
    <collision>
      <origin xyz="0 0 0" rpy="0 0 0" />
      <geometry>
        <mesh filename="package://surenaV_description/meshes/l_hip_yaw.STL" />
      </geometry>
    </collision>
  </link>
  <joint name="l_hip_yaw_joint" type="revolute">
    <origin xyz="0.043012 0.1 0.86631" rpy="0 0 0" />
    <parent link="base_link" />
    <child link="l_hip_yaw" />
    <axis xyz="0 0 1" />
    <limit lower="-1.57" upper="1.57" effort="1000" velocity="0.5" />
    <dynamics damping="0.7" friction="0.3" />
  </joint>

  <link name="l_hip_roll">
    <inertial>
      <origin xyz="0.0033793 -0.012172 0.00021004" rpy="0 0 0" />
      <mass value="2.44" />
      <inertia ixx="0.01" ixy="0.00" ixz="0.00" iyy="0.00" iyz="0.00" izz="0.01" />
    </inertial>
    <visual>
      <origin xyz="0 0 0" rpy="0 0 0" />
      <geometry>
        <mesh filename="package://surenaV_description/meshes/l_hip_roll.STL" />
      </geometry>
      <material name="">
        <color rgba="0.79216 0.81961 0.93333 1" />
      </material>
    </visual>
    <collision>
      <origin xyz="0 0 0" rpy="0 0 0" />
      <geometry>
        <mesh filename="package://surenaV_description/meshes/l_hip_roll.STL" />
      </geometry>
    </collision>
  </link>
  <joint name="l_hip_roll_joint" type="revolute">
    <origin xyz="0 0 -0.1013" rpy="0 0 0" />
    <parent link="l_hip_yaw" />
    <child link="l_hip_roll" />
    <axis xyz="1 0 0" />
    <limit lower="-1.57" upper="1.57" effort="1000" velocity="0.5" />
    <dynamics damping="0.7" friction="0.3" />
  </joint>

  <link name="l_hip_pitch">
    <inertial>
      <origin xyz="0.0024199 -0.02 -0.17825" rpy="0 0 0" />
      <mass value="5.61" />
      <inertia ixx="0.05" ixy="0.00" ixz="0.00" iyy="0.04" iyz="0.00" izz="0.02" />
    </inertial>
    <visual>
      <origin xyz="0 0 0" rpy="0 0 0" />
      <geometry>
        <mesh filename="package://surenaV_description/meshes/l_hip_pitch.STL" />
      </geometry>
      <material name="">
        <color rgba="0.79216 0.81961 0.93333 1" />
      </material>
    </visual>
    <collision>
      <origin xyz="0 0 0" rpy="0 0 0" />
      <geometry>
        <mesh filename="package://surenaV_description/meshes/l_hip_pitch.STL" />
      </geometry>
    </collision>
  </link>
  <joint name="l_hip_pitch_joint" type="revolute">
    <origin xyz="0 0 0" rpy="0 0 0" />
    <parent link="l_hip_roll" />
    <child link="l_hip_pitch" />
    <axis xyz="0 1 0" />
    <limit lower="-1.57" upper="1.57" effort="1000" velocity="0.5" />
    <dynamics damping="0.7" friction="0.3" />
  </joint>

  <link name="l_knee">
    <inertial>
      <origin xyz="0.01 -0.01 -0.09" rpy="0 0 0" />
      <mass value="2.19" />
      <inertia ixx="0.03" ixy="0.00" ixz="0.00" iyy="0.03" iyz="0.00" izz="0.01" />
    </inertial>
    <visual>
      <origin xyz="0 0 0" rpy="0 0 0" />
      <geometry>
        <mesh filename="package://surenaV_description/meshes/l_knee.STL" />
      </geometry>
      <material name="">
        <color rgba="0.79216 0.81961 0.93333 1" />
      </material>
    </visual>
    <collision>
      <origin xyz="0 0 0" rpy="0 0 0" />
      <geometry>
        <mesh filename="package://surenaV_description/meshes/l_knee.STL" />
      </geometry>
    </collision>
  </link>
  <joint name="l_knee_joint" type="revolute">
    <origin xyz="0 0 -0.35988" rpy="0 0 0" />
    <parent link="l_hip_pitch" />
    <child link="l_knee" />
    <axis xyz="0 1 0" />
    <limit lower="-1.57" upper="1.57" effort="1000" velocity="0.5" />
    <dynamics damping="0.7" friction="0.3" />
  </joint>

  <link name="l_ankle_pitch">
    <inertial>
      <origin xyz="-1.3629E-05 -0.01 0.0015737" rpy="0 0 0" />
      <mass value="0.19" />
      <inertia ixx="0" ixy="0" ixz="0" iyy="0" iyz="0" izz="0" />
    </inertial>
    <visual>
      <origin xyz="0 0 0" rpy="0 0 0" />
      <geometry>
        <mesh filename="package://surenaV_description/meshes/l_ankle_pitch.STL" />
      </geometry>
      <material name="">
        <color rgba="0.79216 0.81961 0.93333 1" />
      </material>
    </visual>
    <collision>
      <origin xyz="0 0 0" rpy="0 0 0" />
      <geometry>
        <mesh filename="package://surenaV_description/meshes/l_ankle_pitch.STL" />
      </geometry>
    </collision>
  </link>
  <joint name="l_ankle_pitch_joint" type="revolute">
    <origin xyz="0 0 -0.34999" rpy="0 0 0" />
    <parent link="l_knee" />
    <child link="l_ankle_pitch" />
    <axis xyz="0 1 0" />
    <limit lower="-1.57" upper="1.57" effort="1000" velocity="0.5" />
    <dynamics damping="0.7" friction="0.3" />
  </joint>

  <link name="l_ankle_roll">
    <inertial>
      <origin xyz="0.032019 -0.0036731 -0.039192" rpy="0 0 0" />
      <mass value="1.85" />
      <inertia ixx="0" ixy="0" ixz="0" iyy="0.1" iyz="0" izz="0.01" />
    </inertial>
    <visual>
      <origin xyz="0 0 0" rpy="0 0 0" />
      <geometry>
        <mesh filename="package://surenaV_description/meshes/l_ankle_roll.STL" />
      </geometry>
      <material name="">
        <color rgba="0.79216 0.81961 0.93333 1" />
      </material>
    </visual>
    <collision>
      <origin xyz="0 0 0" rpy="0 0 0" />
      <geometry>
        <mesh filename="package://surenaV_description/meshes/l_ankle_roll.STL" />
      </geometry>
      <surface>
        <friction>
          <ode>
            <mu>100</mu>
            <mu2>100</mu2>
          </ode>
        </friction>
      </surface>
    </collision>
  </link>
  <joint name="l_ankle_roll_joint" type="revolute">
    <origin xyz="0 0 0" rpy="0 0 0" />
    <parent link="l_ankle_pitch" />
    <child link="l_ankle_roll" />
    <axis xyz="1 0 0" />
    <limit lower="-1.57" upper="1.57" effort="1000" velocity="0.5" />
    <dynamics damping="0.7" friction="0.3" />
  </joint>

  <!-- RIGHT ARM -->
  <link name="r_arm_pitch">
    <inertial>
      <origin xyz="-0.01 -0.04 0" rpy="0 0 0" />
      <mass value="1.99" />
      <inertia ixx="0.31" ixy="-0.04" ixz="0.03" iyy="0.08" iyz="0.02" izz="0.3" />
    </inertial>
    <visual>
      <origin xyz="0 0 0" rpy="0 0 0" />
      <geometry>
        <mesh filename="package://surenaV_description/meshes/r_arm_pitch.STL" />
      </geometry>
      <material name="">
        <color rgba="0.79216 0.81961 0.93333 1" />
      </material>
    </visual>
    <collision>
      <origin xyz="0 0 0" rpy="0 0 0" />
      <geometry>
        <mesh filename="package://surenaV_description/meshes/r_arm_pitch.STL" />
      </geometry>
    </collision>
  </link>
  <joint name="r_arm_pitch_joint" type="revolute">
    <origin xyz="0.050262 -0.18726 1.2635" rpy="0 0 0" />
    <parent link="base_link" />
    <child link="r_arm_pitch" />
    <axis xyz="0 1 0" />
    <limit lower="-1.57" upper="1.57" effort="1000" velocity="0.5" />
    <dynamics damping="0.7" friction="0.3" />
  </joint>

  <link name="r_arm_roll">
    <inertial>
      <origin xyz="-0.033422 -0.00012632 -0.083394" rpy="0 0 0" />
      <mass value="1.93" />
      <inertia ixx="0.29" ixy="-0.04" ixz="0.03" iyy="0.07" iyz="-0.02" izz="0.28" />
    </inertial>
    <visual>
      <origin xyz="0 0 0" rpy="0 0 0" />
      <geometry>
        <mesh filename="package://surenaV_description/meshes/r_arm_roll.STL" />
      </geometry>
      <material name="">
        <color rgba="0.79216 0.81961 0.93333 1" />
      </material>
    </visual>
    <collision>
      <origin xyz="0 0 0" rpy="0 0 0" />
      <geometry>
        <mesh filename="package://surenaV_description/meshes/r_arm_roll.STL" />
      </geometry>
    </collision>
  </link>
  <joint name="r_arm_roll_joint" type="revolute">
    <origin xyz="0.035 -0.05 0" rpy="0 0 0" />
    <parent link="r_arm_pitch" />
    <child link="r_arm_roll" />
    <axis xyz="1 0 0" />
    <limit lower="-1.57" upper="1.57" effort="1000" velocity="0.5" />
    <dynamics damping="0.7" friction="0.3" />
  </joint>

  <link name="r_elbow_pitch">
    <inertial>
      <origin xyz="0 0 -0.06" rpy="0 0 0" />
      <mass value="1.91" />
      <inertia ixx="0.28" ixy="-0.04" ixz="0.03" iyy="0.06" iyz="-0.03" izz="0.28" />
    </inertial>
    <visual>
      <origin xyz="0 0 0" rpy="0 0 0" />
      <geometry>
        <mesh filename="package://surenaV_description/meshes/r_elbow_pitch.STL" />
      </geometry>
      <material name="">
        <color rgba="0.79216 0.81961 0.93333 1" />
      </material>
    </visual>
    <collision>
      <origin xyz="0 0 0" rpy="0 0 0" />
      <geometry>
        <mesh filename="package://surenaV_description/meshes/r_elbow_pitch.STL" />
      </geometry>
    </collision>
  </link>
  <joint name="r_elbow_pitch_joint" type="revolute">
    <origin xyz="-0.033004 0 -0.13334" rpy="0 0 0" />
    <parent link="r_arm_roll" />
    <child link="r_elbow_pitch" />
    <axis xyz="0 0 1" />
    <limit lower="-1.57" upper="1.57" effort="1000" velocity="0.5" />
    <dynamics damping="0.7" friction="0.3" />
  </joint>

  <link name="r_forearm_roll">
    <inertial>
      <origin xyz="0 -0.030836 -0.02" rpy="0 0 0" />
      <mass value="2.02" />
      <inertia ixx="0.31" ixy="-0.03" ixz="-0.03" iyy="0.07" iyz="0.03" izz="0.31" />
    </inertial>
    <visual>
      <origin xyz="0 0 0" rpy="0 0 0" />
      <geometry>
        <mesh filename="package://surenaV_description/meshes/r_forearm_roll.STL" />
      </geometry>
      <material name="">
        <color rgba="0.79216 0.81961 0.93333 1" />
      </material>
    </visual>
    <collision>
      <origin xyz="0 0 0" rpy="0 0 0" />
      <geometry>
        <mesh filename="package://surenaV_description/meshes/r_forearm_roll.STL" />
      </geometry>
    </collision>
  </link>
  <joint name="r_forearm_roll_joint" type="revolute">
    <origin xyz="0 0.0335 -0.12309" rpy="0 0 0" />
    <parent link="r_elbow_pitch" />
    <child link="r_forearm_roll" />
    <axis xyz="0 1 0" />
    <limit lower="-1.57" upper="1.57" effort="1000" velocity="0.5" />
    <dynamics damping="0.7" friction="0.3" />
  </joint>

  <link name="r_forearm_link">
    <inertial>
      <origin xyz="0 -0.01 -0.07" rpy="0 0 0" />
      <mass value="0.18" />
      <inertia ixx="0" ixy="0" ixz="0" iyy="0" iyz="0" izz="0" />
    </inertial>
    <visual>
      <origin xyz="0 0 0" rpy="0 0 0" />
      <geometry>
        <mesh filename="package://surenaV_description/meshes/r_forearm_link.STL" />
      </geometry>
      <material name="">
        <color rgba="0.79216 0.81961 0.93333 1" />
      </material>
    </visual>
    <collision>
      <origin xyz="0 0 0" rpy="0 0 0" />
      <geometry>
        <mesh filename="package://surenaV_description/meshes/r_forearm_link.STL" />
      </geometry>
    </collision>
  </link>
  <joint name="r_forearm_link_joint" type="revolute">
    <origin xyz="0 -0.03075 -0.07083" rpy="0 0 -1.57" />
    <parent link="r_forearm_roll" />
    <child link="r_forearm_link" />
    <axis xyz="0 0 1" />
    <limit lower="-1.57" upper="1.57" effort="1000" velocity="0.5" />
    <dynamics damping="0.7" friction="0.3" />
  </joint>

  <link name="r_hand_pitch">
    <inertial>
      <origin xyz="-0.01 3.8223E-08 -5.6648E-09" rpy="0 0 0" />
      <mass value="1.75" />
      <inertia ixx="0.09" ixy="0.03" ixz="-0.08" iyy="0.22" iyz="-0.03" izz="0.19" />
    </inertial>
    <visual>
      <origin xyz="0 0 0" rpy="0 0 0" />
      <geometry>
        <mesh filename="package://surenaV_description/meshes/r_hand_pitch.STL" />
      </geometry>
      <material name="">
        <color rgba="0.79216 0.81961 0.93333 1" />
      </material>
    </visual>
    <collision>
      <origin xyz="0 0 0" rpy="0 0 0" />
      <geometry>
        <mesh filename="package://surenaV_description/meshes/r_hand_pitch.STL" />
      </geometry>
    </collision>
  </link>
  <joint name="r_hand_pitch_joint" type="revolute">
    <origin xyz="0.01 0 -0.15132" rpy="0 0 0" />
    <parent link="r_forearm_link" />
    <child link="r_hand_pitch" />
    <axis xyz="0 -1 0" />
    <limit lower="-1.57" upper="1.57" effort="1000" velocity="0.5" />
    <dynamics damping="0.7" friction="0.3" />
  </joint>

  <link name="r_hand_roll">
    <inertial>
      <origin xyz="0.0041621 -0.017 -0.012245" rpy="0 0 0" />
      <mass value="1.75" />
      <inertia ixx="0.05" ixy="0.04" ixz="0.02" iyy="0.22" iyz="-0.01" izz="0.23" />
    </inertial>
    <visual>
      <origin xyz="0 0 0" rpy="0 0 0" />
      <geometry>
        <mesh filename="package://surenaV_description/meshes/r_hand_roll.STL" />
      </geometry>
      <material name="">
        <color rgba="0.79216 0.81961 0.93333 1" />
      </material>
    </visual>
    <collision>
      <origin xyz="0 0 0" rpy="0 0 0" />
      <geometry>
        <mesh filename="package://surenaV_description/meshes/r_hand_roll.STL" />
      </geometry>
    </collision>
  </link>
  <joint name="r_hand_roll_joint" type="revolute">
    <origin xyz="-0.01 0.017 0" rpy="0 0 0" />
    <parent link="r_hand_pitch" />
    <child link="r_hand_roll" />
    <axis xyz="1 0 0" />
    <limit lower="-1.57" upper="1.57" effort="1000" velocity="0.5" />
    <dynamics damping="0.7" friction="0.3" />
  </joint>

  <link name="r_hand_link">
    <inertial>
      <origin xyz="-0.01 0.01 -0.07" rpy="0 0 0" />
      <mass value="0.24" />
      <inertia ixx="0" ixy="0" ixz="0" iyy="0" iyz="0" izz="0" />
    </inertial>
    <visual>
      <origin xyz="0 0 0" rpy="0 0 0" />
      <geometry>
        <mesh filename="package://surenaV_description/meshes/r_hand_link.STL" />
      </geometry>
      <material name="">
        <color rgba="0.79216 0.81961 0.93333 1" />
      </material>
    </visual>
    <collision>
      <origin xyz="0 0 0" rpy="0 0 0" />
      <geometry>
        <mesh filename="package://surenaV_description/meshes/r_hand_link.STL" />
      </geometry>
    </collision>
  </link>
  <joint name="r_hand_link_joint" type="fixed">
    <origin xyz="0.049842 0.21551 0.7191" rpy="0 0 0" />
    <parent link="r_hand_roll" />
    <child link="r_hand_link" />
    <axis xyz="0 0 0" />
  </joint>

  <!-- LEFT ARM -->
  <link name="l_arm_pitch">
    <inertial>
      <origin xyz="-0.01 0.042591 -0.00039657" rpy="0 0 0" />
      <mass value="1.99" />
      <inertia ixx="0.28" ixy="-0.08" ixz="0.04" iyy="0.1" iyz="-0.02" izz="0.3" />
    </inertial>
    <visual>
      <origin xyz="0 0 0" rpy="0 0 0" />
      <geometry>
        <mesh filename="package://surenaV_description/meshes/l_arm_pitch.STL" />
      </geometry>
      <material name="">
        <color rgba="0.79216 0.81961 0.93333 1" />
      </material>
    </visual>
    <collision>
      <origin xyz="0 0 0" rpy="0 0 0" />
      <geometry>
        <mesh filename="package://surenaV_description/meshes/l_arm_pitch.STL" />
      </geometry>
    </collision>
  </link>
  <joint name="l_arm_pitch_joint" type="revolute">
    <origin xyz="0.050262 0.18852 1.2635" rpy="0 0 0" />
    <parent link="base_link" />
    <child link="l_arm_pitch" />
    <axis xyz="0 1 0" />
    <limit lower="-1.57" upper="1.57" effort="1000" velocity="0.5" />
    <dynamics damping="0.7" friction="0.3" />
  </joint>

  <link name="l_arm_roll">
    <inertial>
      <origin xyz="-0.033422 0.00012632 -0.083394" rpy="0 0 0" />
      <mass value="1.93" />
      <inertia ixx="0.26" ixy="-0.08" ixz="0.03" iyy="0.1" iyz="-0.01" izz="0.28" />
    </inertial>
    <visual>
      <origin xyz="0 0 0" rpy="0 0 0" />
      <geometry>
        <mesh filename="package://surenaV_description/meshes/l_arm_roll.STL" />
      </geometry>
      <material name="">
        <color rgba="0.79216 0.81961 0.93333 1" />
      </material>
    </visual>
    <collision>
      <origin xyz="0 0 0" rpy="0 0 0" />
      <geometry>
        <mesh filename="package://surenaV_description/meshes/l_arm_roll.STL" />
      </geometry>
    </collision>
  </link>
  <joint name="l_arm_roll_joint" type="revolute">
    <origin xyz="0.035 0.05 0" rpy="0 0 0" />
    <parent link="l_arm_pitch" />
    <child link="l_arm_roll" />
    <axis xyz="1 0 0" />
    <limit lower="-1.57" upper="1.57" effort="1000" velocity="0.5" />
    <dynamics damping="0.7" friction="0.3" />
  </joint>

  <link name="l_elbow_pitch">
    <inertial>
      <origin xyz="2.12E-06 -0.0028416 -0.06" rpy="0 0 0" />
      <mass value="1.91" />
      <inertia ixx="0.25" ixy="-0.08" ixz="0.04" iyy="0.09" iyz="-0.03" izz="0.28" />
    </inertial>
    <visual>
      <origin xyz="0 0 0" rpy="0 0 0" />
      <geometry>
        <mesh filename="package://surenaV_description/meshes/l_elbow_pitch.STL" />
      </geometry>
      <material name="">
        <color rgba="0.79216 0.81961 0.93333 1" />
      </material>
    </visual>
    <collision>
      <origin xyz="0 0 0" rpy="0 0 0" />
      <geometry>
        <mesh filename="package://surenaV_description/meshes/l_elbow_pitch.STL" />
      </geometry>
    </collision>
  </link>
  <joint name="l_elbow_pitch_joint" type="revolute">
    <origin xyz="-0.033004 0 -0.13334" rpy="0 0 0" />
    <parent link="l_arm_roll" />
    <child link="l_elbow_pitch" />
    <axis xyz="0 0 1" />
    <limit lower="-1.57" upper="1.57" effort="1000" velocity="0.5" />
    <dynamics damping="0.7" friction="0.3" />
  </joint>

  <link name="l_forearm_roll">
    <inertial>
      <origin xyz="0 0.030836 -0.02" rpy="0 0 0" />
      <mass value="2.02" />
      <inertia ixx="0.31" ixy="-0.03" ixz="-0.03" iyy="0.09" iyz="0.08" izz="0.28" />
    </inertial>
    <visual>
      <origin xyz="0 0 0" rpy="0 0 0" />
      <geometry>
        <mesh filename="package://surenaV_description/meshes/l_forearm_roll.STL" />
      </geometry>
      <material name="">
        <color rgba="0.79216 0.81961 0.93333 1" />
      </material>
    </visual>
    <collision>
      <origin xyz="0 0 0" rpy="0 0 0" />
      <geometry>
        <mesh filename="package://surenaV_description/meshes/l_forearm_roll.STL" />
      </geometry>
    </collision>
  </link>
  <joint name="l_forearm_roll_joint" type="revolute">
    <origin xyz="0 -0.0325 -0.12309" rpy="0 0 0" />
    <parent link="l_elbow_pitch" />
    <child link="l_forearm_roll" />
    <axis xyz="0 1 0" />
    <limit lower="-1.57" upper="1.57" effort="1000" velocity="0.5" />
    <dynamics damping="0.7" friction="0.3" />
  </joint>

  <link name="l_forearm_link">
    <inertial>
      <origin xyz="-0.00059087 0.01 -0.072286" rpy="0 0 1.57" />
      <mass value="0.18" />
      <inertia ixx="0" ixy="0" ixz="0" iyy="0" iyz="0" izz="0" />
    </inertial>
    <visual>
      <origin xyz="0 0 0" rpy="0 0 0" />
      <geometry>
        <mesh filename="package://surenaV_description/meshes/l_forearm_link.STL" />
      </geometry>
      <material name="">
        <color rgba="0.79216 0.81961 0.93333 1" />
      </material>
    </visual>
    <collision>
      <origin xyz="0 0 0" rpy="0 0 0" />
      <geometry>
        <mesh filename="package://surenaV_description/meshes/l_forearm_link.STL" />
      </geometry>
    </collision>
  </link>
  <joint name="l_forearm_link_joint" type="revolute">
    <origin xyz="0 0.03075 -0.07083" rpy="0 0 1.57" />
    <parent link="l_forearm_roll" />
    <child link="l_forearm_link" />
    <axis xyz="0 0 -1" />
    <limit lower="-1.57" upper="1.57" effort="1000" velocity="0.5" />
    <dynamics damping="0.7" friction="0.3" />
  </joint>

  <link name="l_hand_pitch">
    <inertial>
      <origin xyz="-0.01 3.8223E-08 5.6648E-09" rpy="0 0 0" />
      <mass value="1.75" />
      <inertia ixx="0.09" ixy="-0.03" ixz="-0.08" iyy="0.22" iyz="0.03" izz="0.19" />
    </inertial>
    <visual>
      <origin xyz="0 0 0" rpy="0 0 0" />
      <geometry>
        <mesh filename="package://surenaV_description/meshes/l_hand_pitch.STL" />
      </geometry>
      <material name="">
        <color rgba="0.79216 0.81961 0.93333 1" />
      </material>
    </visual>
    <collision>
      <origin xyz="0 0 0" rpy="0 0 0" />
      <geometry>
        <mesh filename="package://surenaV_description/meshes/l_hand_pitch.STL" />
      </geometry>
    </collision>
  </link>
  <joint name="l_hand_pitch_joint" type="revolute">
    <origin xyz="0.01 0 -0.15132" rpy="0 0 0" />
    <parent link="l_forearm_link" />
    <child link="l_hand_pitch" />
    <axis xyz="0 -1 0" />
    <limit lower="-1.57" upper="1.57" effort="1000" velocity="0.5" />
    <dynamics damping="0.7" friction="0.3" />
  </joint>

  <link name="l_hand_roll">
    <inertial>
      <origin xyz="0.0041621 0.02 -0.012245" rpy="0 0 0" />
      <mass value="1.75" />
      <inertia ixx="0.16" ixy="0.01" ixz="0.09" iyy="0.22" iyz="0.04" izz="0.13" />
    </inertial>
    <visual>
      <origin xyz="0 0 0" rpy="0 0 0" />
      <geometry>
        <mesh filename="package://surenaV_description/meshes/l_hand_roll.STL" />
      </geometry>
      <material name="">
        <color rgba="0.79216 0.81961 0.93333 1" />
      </material>
    </visual>
    <collision>
      <origin xyz="0 0 0" rpy="0 0 0" />
      <geometry>
        <mesh filename="package://surenaV_description/meshes/l_hand_roll.STL" />
      </geometry>
    </collision>
  </link>
  <joint name="l_hand_roll_joint" type="revolute">
    <origin xyz="-0.01 -0.017 0" rpy="0 0 0" />
    <parent link="l_hand_pitch" />
    <child link="l_hand_roll" />
    <axis xyz="1 0 0" />
    <limit lower="-1.57" upper="1.57" effort="1000" velocity="0.5" />
    <dynamics damping="0.7" friction="0.3" />
  </joint>

  <link name="l_hand_link">
    <inertial>
      <origin xyz="0.0031894 0.011871 -0.076128" rpy="0 0 0" />
      <mass value="0.24" />
      <inertia ixx="0" ixy="0" ixz="0" iyy="0" iyz="0" izz="0" />
    </inertial>
    <visual>
      <origin xyz="0 0 0" rpy="0 0 0" />
      <geometry>
        <mesh filename="package://surenaV_description/meshes/l_hand_link.STL" />
      </geometry>
      <material name="">
        <color rgba="0.79216 0.81961 0.93333 1" />
      </material>
    </visual>
    <collision>
      <origin xyz="0 0 0" rpy="0 0 0" />
      <geometry>
        <mesh filename="package://surenaV_description/meshes/l_hand_link.STL" />
      </geometry>
    </collision>
  </link>
  <joint name="l_hand_link_joint" type="fixed">
    <origin xyz="0 0 0" rpy="0 0 0" />
    <parent link="l_hand_roll" />
    <child link="l_hand_link" />
    <axis xyz="0 0 0" />
  </joint>

  <!-- CAMERA -->
  <link name="camera_link">
    <inertial>
      <origin xyz="0 0 0" rpy="-1.57 -1.57 -1.57"/>
      <mass value="0.1"/>
      <inertia ixx="0.0001" ixy="0" ixz="0" iyy="0.0001" iyz="0" izz="0.0001"/>
    </inertial>
    <visual>
      <origin xyz="0 0 0" rpy="0 0 0"/>
      <geometry>
        <box size="0.01 0.07 0.015"/>
      </geometry>
      <material name="gray">
        <color rgba="0.5 0.5 0.5 1"/>
      </material>
    </visual>
    <collision>
      <origin xyz="0 0 0" rpy="0 0 0"/>
      <geometry>
        <box size="0.01 0.07 0.015"/>
      </geometry>
    </collision>
  </link>
  <joint name="camera_joint" type="fixed">
    <parent link="head_roll"/>
    <child link="camera_link"/>
    <origin xyz="0.085 0 0.068" rpy="0 0.349 0"/>
  </joint>
  

  <!-- ===================================================================================== -->
  <!-- |                             CAMERA AND SENSORS                                    | -->
  <!-- ===================================================================================== -->
  <gazebo reference="camera_link">
    <sensor name="camera1" type="depth">
      <always_on>true</always_on>
      <update_rate>10.0</update_rate>
      <camera>
        <horizontal_fov>2</horizontal_fov>
        <image>
          <format>R8G8B8</format>
          <width>1080</width>
          <height>720</height>
        </image>
        <clip>
          <near>0.5</near>
          <far>30.0</far>
        </clip>
      </camera>
      <plugin filename="libgazebo_ros_openni_kinect.so" name="camera_depth_frame_kinect_controller">
        <baseline>0.2</baseline>
        <alwaysOn>true</alwaysOn>
        <updateRate>0</updateRate>
        <cameraName>camera</cameraName>
        <imageTopicName>image_raw</imageTopicName>
        <cameraInfoTopicName>camera_info</cameraInfoTopicName>
        <depthImageTopicName>depth/image_raw</depthImageTopicName>
        <depthImageCameraInfoTopicName>depth/camera_info</depthImageCameraInfoTopicName>
        <pointCloudTopicName>depth/points</pointCloudTopicName>
        <frameName>camera_depth_optical_frame</frameName>
        <pointCloudCutoff>0.5</pointCloudCutoff>
        <pointCloudCutoffMax>3.0</pointCloudCutoffMax>
        <distortionK1>0.00000001</distortionK1>
        <distortionK2>0.00000001</distortionK2>
        <distortionK3>0.00000001</distortionK3>
        <distortionT1>0.00000001</distortionT1>
        <distortionT2>0.00000001</distortionT2>
        <CxPrime>0</CxPrime>
        <Cx>0</Cx>
        <Cy>0</Cy>
        <focalLength>0</focalLength>
        <hackBaseline>0</hackBaseline>
      </plugin>
    </sensor>
  </gazebo>


  <!-- ===================================================================================== -->
  <!-- |                       PHYSICAL PROPERTIES (GAZEBO)                                | -->
  <!-- ===================================================================================== -->

  <!-- HEAD -->
  <gazebo reference="head_yaw">
    <mu1>0.9</mu1>
    <mu2>0.9</mu2>
  </gazebo>
  <gazebo reference="head_pitch">
    <mu1>0.9</mu1>
    <mu2>0.9</mu2>
  </gazebo>
  <gazebo reference="head_roll">
    <mu1>0.9</mu1>
    <mu2>0.9</mu2>
  </gazebo>

  <!-- RIGHT LEG -->
  <gazebo reference="r_hip_yaw">
    <mu1>0.9</mu1>
    <mu2>0.9</mu2>
  </gazebo>
  <gazebo reference="r_hip_roll">
    <mu1>0.9</mu1>
    <mu2>0.9</mu2>
  </gazebo>
  <gazebo reference="r_hip_pitch">
    <mu1>0.9</mu1>
    <mu2>0.9</mu2>
  </gazebo>
  <gazebo reference="r_knee">
    <mu1>0.9</mu1>
    <mu2>0.9</mu2>
  </gazebo>
  <gazebo reference="r_ankle_pitch">
    <mu1>0.9</mu1>
    <mu2>0.9</mu2>
  </gazebo>
  <gazebo reference="r_ankle_roll">
    <mu1>1000</mu1>
    <mu2>1000</mu2>
    <kp>1000000.0</kp>
    <kd>100000.0</kd>
    <slip1>0</slip1>
    <slip2>0</slip2>
  </gazebo>

  <!-- LEFT LEG -->
  <gazebo reference="l_hip_yaw">
    <mu1>0.9</mu1>
    <mu2>0.9</mu2>
  </gazebo>
  <gazebo reference="l_hip_roll">
    <mu1>0.9</mu1>
    <mu2>0.9</mu2>
  </gazebo>
  <gazebo reference="l_hip_pitch">
    <mu1>0.9</mu1>
    <mu2>0.9</mu2>
  </gazebo>
  <gazebo reference="l_knee">
    <mu1>0.9</mu1>
    <mu2>0.9</mu2>
  </gazebo>
  <gazebo reference="l_ankle_pitch">
    <mu1>0.9</mu1>
    <mu2>0.9</mu2>
  </gazebo>
  <gazebo reference="l_ankle_roll">
    <mu1>1000</mu1>
    <mu2>1000</mu2>
    <kp>1000000.0</kp>
    <kd>100000.0</kd>
    <slip1>0</slip1>
    <slip2>0</slip2>
  </gazebo>

  <!-- RIGHT ARM -->
  <gazebo reference="r_arm_pitch">
    <mu1>0.9</mu1>
    <mu2>0.9</mu2>
  </gazebo>
  <gazebo reference="r_arm_roll">
    <mu1>0.9</mu1>
    <mu2>0.9</mu2>
  </gazebo>
  <gazebo reference="r_elbow_pitch">
    <mu1>0.9</mu1>
    <mu2>0.9</mu2>
  </gazebo>
  <gazebo reference="r_forearm_roll">
    <mu1>0.9</mu1>
    <mu2>0.9</mu2>
  </gazebo>
  <gazebo reference="r_forearm_link">
    <mu1>0.9</mu1>
    <mu2>0.9</mu2>
  </gazebo>
  <gazebo reference="r_hand_pitch">
    <mu1>0.9</mu1>
    <mu2>0.9</mu2>
  </gazebo>
  <gazebo reference="r_hand_roll">
    <mu1>0.9</mu1>
    <mu2>0.9</mu2>
  </gazebo>
  <gazebo reference="r_hand_link">
    <mu1>0.9</mu1>
    <mu2>0.9</mu2>
  </gazebo>

  <!-- LEFT ARM -->
  <gazebo reference="l_arm_pitch">
    <mu1>0.9</mu1>
    <mu2>0.9</mu2>
  </gazebo>
  <gazebo reference="l_arm_roll">
    <mu1>0.9</mu1>
    <mu2>0.9</mu2>
  </gazebo>
  <gazebo reference="l_elbow_pitch">
    <mu1>0.9</mu1>
    <mu2>0.9</mu2>
  </gazebo>
  <gazebo reference="l_forearm_roll">
    <mu1>0.9</mu1>
    <mu2>0.9</mu2>
  </gazebo>
  <gazebo reference="l_forearm_link">
    <mu1>0.9</mu1>
    <mu2>0.9</mu2>
  </gazebo>
  <gazebo reference="l_hand_pitch">
    <mu1>0.9</mu1>
    <mu2>0.9</mu2>
  </gazebo>
  <gazebo reference="l_hand_roll">
    <mu1>0.9</mu1>
    <mu2>0.9</mu2>
  </gazebo>
  <gazebo reference="l_hand_link">
    <mu1>0.9</mu1>
    <mu2>0.9</mu2>
  </gazebo>


  <!-- ===================================================================================== -->
  <!-- |                                  TRANSMISSIONS                                    | -->
  <!-- ===================================================================================== -->

  <!-- HEAD -->
  <transmission name="head_yaw_tran">
    <type>transmission_interface/SimpleTransmission</type>
    <joint name="head_yaw_joint">
      <hardwareInterface>hardware_interface/EffortJointInterface</hardwareInterface>
    </joint>
    <actuator name="head_yaw_motor">
      <hardwareInterface>hardware_interface/EffortJointInterface</hardwareInterface>
      <mechanicalReduction>1</mechanicalReduction>
    </actuator>
  </transmission>
  <transmission name="head_pitch_tran">
    <type>transmission_interface/SimpleTransmission</type>
    <joint name="head_pitch_joint">
      <hardwareInterface>hardware_interface/EffortJointInterface</hardwareInterface>
    </joint>
    <actuator name="head_pitch_motor">
      <hardwareInterface>hardware_interface/EffortJointInterface</hardwareInterface>
      <mechanicalReduction>1</mechanicalReduction>
    </actuator>
  </transmission>
  <transmission name="head_roll_tran">
    <type>transmission_interface/SimpleTransmission</type>
    <joint name="head_roll_joint">
      <hardwareInterface>hardware_interface/EffortJointInterface</hardwareInterface>
    </joint>
    <actuator name="head_roll_motor">
      <hardwareInterface>hardware_interface/EffortJointInterface</hardwareInterface>
      <mechanicalReduction>1</mechanicalReduction>
    </actuator>
  </transmission>

  <!-- RIGHT LEG -->
  <transmission name="r_hip_yaw_tran">
    <type>transmission_interface/SimpleTransmission</type>
    <joint name="r_hip_yaw_joint">
      <hardwareInterface>hardware_interface/EffortJointInterface</hardwareInterface>
    </joint>
    <actuator name="r_hip_yaw_motor">
      <hardwareInterface>hardware_interface/EffortJointInterface</hardwareInterface>
      <mechanicalReduction>1</mechanicalReduction>
    </actuator>
  </transmission>
  <transmission name="r_hip_roll_tran">
    <type>transmission_interface/SimpleTransmission</type>
    <joint name="r_hip_roll_joint">
      <hardwareInterface>hardware_interface/EffortJointInterface</hardwareInterface>
    </joint>
    <actuator name="r_hip_roll_motor">
      <hardwareInterface>hardware_interface/EffortJointInterface</hardwareInterface>
      <mechanicalReduction>1</mechanicalReduction>
    </actuator>
  </transmission>
  <transmission name="r_hip_pitch_tran">
    <type>transmission_interface/SimpleTransmission</type>
    <joint name="r_hip_pitch_joint">
      <hardwareInterface>hardware_interface/EffortJointInterface</hardwareInterface>
    </joint>
    <actuator name="r_hip_pitch_motor">
      <hardwareInterface>hardware_interface/EffortJointInterface</hardwareInterface>
      <mechanicalReduction>1</mechanicalReduction>
    </actuator>
  </transmission>
  <transmission name="r_knee_tran">
    <type>transmission_interface/SimpleTransmission</type>
    <joint name="r_knee_joint">
      <hardwareInterface>hardware_interface/EffortJointInterface</hardwareInterface>
    </joint>
    <actuator name="r_knee_motor">
      <hardwareInterface>hardware_interface/EffortJointInterface</hardwareInterface>
      <mechanicalReduction>1</mechanicalReduction>
    </actuator>
  </transmission>
  <transmission name="r_ankle_pitch_tran">
    <type>transmission_interface/SimpleTransmission</type>
    <joint name="r_ankle_pitch_joint">
      <hardwareInterface>hardware_interface/EffortJointInterface</hardwareInterface>
    </joint>
    <actuator name="r_ankle_pitch_motor">
      <hardwareInterface>hardware_interface/EffortJointInterface</hardwareInterface>
      <mechanicalReduction>1</mechanicalReduction>
    </actuator>
  </transmission>
  <transmission name="r_ankle_roll_tran">
    <type>transmission_interface/SimpleTransmission</type>
    <joint name="r_ankle_roll_joint">
      <hardwareInterface>hardware_interface/EffortJointInterface</hardwareInterface>
    </joint>
    <actuator name="r_ankle_roll_motor">
      <hardwareInterface>hardware_interface/EffortJointInterface</hardwareInterface>
      <mechanicalReduction>1</mechanicalReduction>
    </actuator>
  </transmission>

  <!-- LEFT LEG -->
  <transmission name="l_hip_yaw_tran">
    <type>transmission_interface/SimpleTransmission</type>
    <joint name="l_hip_yaw_joint">
      <hardwareInterface>hardware_interface/EffortJointInterface</hardwareInterface>
    </joint>
    <actuator name="l_hip_yaw_motor">
      <hardwareInterface>hardware_interface/EffortJointInterface</hardwareInterface>
      <mechanicalReduction>1</mechanicalReduction>
    </actuator>
  </transmission>
  <transmission name="l_hip_roll_tran">
    <type>transmission_interface/SimpleTransmission</type>
    <joint name="l_hip_roll_joint">
      <hardwareInterface>hardware_interface/EffortJointInterface</hardwareInterface>
    </joint>
    <actuator name="l_hip_roll_motor">
      <hardwareInterface>hardware_interface/EffortJointInterface</hardwareInterface>
      <mechanicalReduction>1</mechanicalReduction>
    </actuator>
  </transmission>
  <transmission name="l_hip_pitch_tran">
    <type>transmission_interface/SimpleTransmission</type>
    <joint name="l_hip_pitch_joint">
      <hardwareInterface>hardware_interface/EffortJointInterface</hardwareInterface>
    </joint>
    <actuator name="l_hip_pitch_motor">
      <hardwareInterface>hardware_interface/EffortJointInterface</hardwareInterface>
      <mechanicalReduction>1</mechanicalReduction>
    </actuator>
  </transmission>
  <transmission name="l_knee_tran">
    <type>transmission_interface/SimpleTransmission</type>
    <joint name="l_knee_joint">
      <hardwareInterface>hardware_interface/EffortJointInterface</hardwareInterface>
    </joint>
    <actuator name="l_knee_motor">
      <hardwareInterface>hardware_interface/EffortJointInterface</hardwareInterface>
      <mechanicalReduction>1</mechanicalReduction>
    </actuator>
  </transmission>
  <transmission name="l_ankle_pitch_tran">
    <type>transmission_interface/SimpleTransmission</type>
    <joint name="l_ankle_pitch_joint">
      <hardwareInterface>hardware_interface/EffortJointInterface</hardwareInterface>
    </joint>
    <actuator name="l_ankle_pitch_motor">
      <hardwareInterface>hardware_interface/EffortJointInterface</hardwareInterface>
      <mechanicalReduction>1</mechanicalReduction>
    </actuator>
  </transmission>
  <transmission name="l_ankle_roll_tran">
    <type>transmission_interface/SimpleTransmission</type>
    <joint name="l_ankle_roll_joint">
      <hardwareInterface>hardware_interface/EffortJointInterface</hardwareInterface>
    </joint>
    <actuator name="l_ankle_roll_motor">
      <hardwareInterface>hardware_interface/EffortJointInterface</hardwareInterface>
      <mechanicalReduction>1</mechanicalReduction>
    </actuator>
  </transmission>

  <!-- RIGHT ARM -->
  <transmission name="r_arm_pitch_tran">
    <type>transmission_interface/SimpleTransmission</type>
    <joint name="r_arm_pitch_joint">
      <hardwareInterface>hardware_interface/EffortJointInterface</hardwareInterface>
    </joint>
    <actuator name="r_arm_pitch_motor">
      <hardwareInterface>hardware_interface/EffortJointInterface</hardwareInterface>
      <mechanicalReduction>1</mechanicalReduction>
    </actuator>
  </transmission>
  <transmission name="r_arm_roll_tran">
    <type>transmission_interface/SimpleTransmission</type>
    <joint name="r_arm_roll_joint">
      <hardwareInterface>hardware_interface/EffortJointInterface</hardwareInterface>
    </joint>
    <actuator name="r_arm_roll_motor">
      <hardwareInterface>hardware_interface/EffortJointInterface</hardwareInterface>
      <mechanicalReduction>1</mechanicalReduction>
    </actuator>
  </transmission>
  <transmission name="r_elbow_pitch_tran">
    <type>transmission_interface/SimpleTransmission</type>
    <joint name="r_elbow_pitch_joint">
      <hardwareInterface>hardware_interface/EffortJointInterface</hardwareInterface>
    </joint>
    <actuator name="r_elbow_pitch_motor">
      <hardwareInterface>hardware_interface/EffortJointInterface</hardwareInterface>
      <mechanicalReduction>1</mechanicalReduction>
    </actuator>
  </transmission>
  <transmission name="r_forearm_roll_tran">
    <type>transmission_interface/SimpleTransmission</type>
    <joint name="r_forearm_roll_joint">
      <hardwareInterface>hardware_interface/EffortJointInterface</hardwareInterface>
    </joint>
    <actuator name="r_forearm_roll_motor">
      <hardwareInterface>hardware_interface/EffortJointInterface</hardwareInterface>
      <mechanicalReduction>1</mechanicalReduction>
    </actuator>
  </transmission>
  <transmission name="r_forearm_link_tran">
    <type>transmission_interface/SimpleTransmission</type>
    <joint name="r_forearm_link_joint">
      <hardwareInterface>hardware_interface/EffortJointInterface</hardwareInterface>
    </joint>
    <actuator name="r_forearm_link_motor">
      <hardwareInterface>hardware_interface/EffortJointInterface</hardwareInterface>
      <mechanicalReduction>1</mechanicalReduction>
    </actuator>
  </transmission>
  <transmission name="r_hand_pitch_tran">
    <type>transmission_interface/SimpleTransmission</type>
    <joint name="r_hand_pitch_joint">
      <hardwareInterface>hardware_interface/EffortJointInterface</hardwareInterface>
    </joint>
    <actuator name="r_hand_pitch_motor">
      <hardwareInterface>hardware_interface/EffortJointInterface</hardwareInterface>
      <mechanicalReduction>1</mechanicalReduction>
    </actuator>
  </transmission>
  <transmission name="r_hand_roll_tran">
    <type>transmission_interface/SimpleTransmission</type>
    <joint name="r_hand_roll_joint">
      <hardwareInterface>hardware_interface/EffortJointInterface</hardwareInterface>
    </joint>
    <actuator name="r_hand_roll_motor">
      <hardwareInterface>hardware_interface/EffortJointInterface</hardwareInterface>
      <mechanicalReduction>1</mechanicalReduction>
    </actuator>
  </transmission>

  <!-- LEFT ARM -->
  <transmission name="l_arm_pitch_tran">
    <type>transmission_interface/SimpleTransmission</type>
    <joint name="l_arm_pitch_joint">
      <hardwareInterface>hardware_interface/EffortJointInterface</hardwareInterface>
    </joint>
    <actuator name="l_arm_pitch_motor">
      <hardwareInterface>hardware_interface/EffortJointInterface</hardwareInterface>
      <mechanicalReduction>1</mechanicalReduction>
    </actuator>
  </transmission>
  <transmission name="l_arm_roll_tran">
    <type>transmission_interface/SimpleTransmission</type>
    <joint name="l_arm_roll_joint">
      <hardwareInterface>hardware_interface/EffortJointInterface</hardwareInterface>
    </joint>
    <actuator name="l_arm_roll_motor">
      <hardwareInterface>hardware_interface/EffortJointInterface</hardwareInterface>
      <mechanicalReduction>1</mechanicalReduction>
    </actuator>
  </transmission>
  <transmission name="l_elbow_pitch_tran">
    <type>transmission_interface/SimpleTransmission</type>
    <joint name="l_elbow_pitch_joint">
      <hardwareInterface>hardware_interface/EffortJointInterface</hardwareInterface>
    </joint>
    <actuator name="l_elbow_pitch_motor">
      <hardwareInterface>hardware_interface/EffortJointInterface</hardwareInterface>
      <mechanicalReduction>1</mechanicalReduction>
    </actuator>
  </transmission>
  <transmission name="l_forearm_roll_tran">
    <type>transmission_interface/SimpleTransmission</type>
    <joint name="l_forearm_roll_joint">
      <hardwareInterface>hardware_interface/EffortJointInterface</hardwareInterface>
    </joint>
    <actuator name="l_forearm_roll_motor">
      <hardwareInterface>hardware_interface/EffortJointInterface</hardwareInterface>
      <mechanicalReduction>1</mechanicalReduction>
    </actuator>
  </transmission>
  <transmission name="l_forearm_link_tran">
    <type>transmission_interface/SimpleTransmission</type>
    <joint name="l_forearm_link_joint">
      <hardwareInterface>hardware_interface/EffortJointInterface</hardwareInterface>
    </joint>
    <actuator name="l_forearm_link_motor">
      <hardwareInterface>hardware_interface/EffortJointInterface</hardwareInterface>
      <mechanicalReduction>1</mechanicalReduction>
    </actuator>
  </transmission>
  <transmission name="l_hand_pitch_tran">
    <type>transmission_interface/SimpleTransmission</type>
    <joint name="l_hand_pitch_joint">
      <hardwareInterface>hardware_interface/EffortJointInterface</hardwareInterface>
    </joint>
    <actuator name="l_hand_pitch_motor">
      <hardwareInterface>hardware_interface/EffortJointInterface</hardwareInterface>
      <mechanicalReduction>1</mechanicalReduction>
    </actuator>
  </transmission>
  <transmission name="l_hand_roll_tran">
    <type>transmission_interface/SimpleTransmission</type>
    <joint name="l_hand_roll_joint">
      <hardwareInterface>hardware_interface/EffortJointInterface</hardwareInterface>
    </joint>
    <actuator name="l_hand_roll_motor">
      <hardwareInterface>hardware_interface/EffortJointInterface</hardwareInterface>
      <mechanicalReduction>1</mechanicalReduction>
    </actuator>
  </transmission>
</robot>